Workbook

Sheet 읽어주세요
A1: 모두의 복약 — 약 × 영양제 조합 추가 입력 양식 (v1, 2026-10-12)
A3: 왜 이 양식인가
A4: 앱의 「1분 복용 점검」은 데이터베이스에 들어 있는 조합 규칙만 보여 줍니다. 앱이 문장을 지어내지 않습니다.
A5: 그래서 연구원님이 적어 주신 「무슨 일이」「어떻게 하면」 문장이 그대로 사용자 화면에 나갑니다. 화면용 문장을 가장 신경 써 주세요.
A7: 어디에 적나 — 노란 칸만 적으시면 됩니다
A8: 시트 ①「새 조합」 : 새로 넣을 약 × 영양제(또는 영양제 × 영양제) 조합. 한 줄 = 조합 하나. 회색 줄 3개는 예시이니 지우지 말고 그 아래부터 적어 주세요.
A9: 시트 ②「새 성분」 : 조합에 쓴 성분·계열 이름이 시트 ④ 목록에 없을 때만 적습니다. 시트 ①의 「목록 확인」 칸이 자동으로 알려 줍니다.
A10: 시트 ③「이미 있는 조합」 : 지금 데이터베이스에 있는 70건. 중복으로 적지 않도록 먼저 훑어봐 주세요. 고칠 것이 있으면 맨 오른쪽 「의견」 칸에 적어 주세요.
A11: 시트 ④「이미 있는 성분·계열」 : 이름 표기를 이 목록과 똑같이 맞춰 주세요 (예: 오메가-3, 비타민 D, 코엔자임 Q10).
A12: 시트 ⑤「용어」 : 등급·근거 수준·조건의 뜻과 고를 수 있는 값. 시트 ①의 드롭다운이 이 시트를 읽습니다.
A14: 꼭 지켜 주실 것 5가지
A15: 1. 한 줄에 조합 하나. 「A × B 또는 C」처럼 여러 조합을 한 줄에 적지 말고 줄을 나눠 주세요. 단, 「PPI × (마그네슘 또는 비타민 B12)」처럼 한쪽이 '둘 중 하나'인 규칙은 B칸에 「마그네슘 / 비타민 B12」로 적고 비고에 '둘 중 하나'라고 써 주세요.
... A27: 칸 색 안내: 노란 칸 = 연구원님이 적는 곳 회색 줄 = 예시(지우지 마세요) 흰 칸 = 자동 계산·참고

Sheet ① 새 조합
A1: 새로 넣을 조합 — 노란 칸만 적어 주세요. 회색 3줄은 예시입니다(지우지 마세요). 「목록 확인」이 '새 성분'이라고 뜨면 시트②에 그 성분을 적어 주세요.
A2: 번호 | B2: A쪽: 약 (성분 또는 계열) | C2: B쪽: 영양제·건기식 (또는 두 번째 약) | D2: 조건 (해당할 때만) | E2: 등급 | F2: 근거 수준 | G2: 요약 한 줄 (화면 제목) | H2: 무슨 일이 (화면) | I2: 어떻게 하면 (화면) | J2: 시간 간격(시간) | K2: 수술 전 중단(일) | L2: 출처 | M2: 기전 요약 (내부용, 선택) | N2: 비고 | O2: 목록 확인 (자동) | P2: 작성자 / 날짜
A3: 예시1 | B3: 와파린 | C3: 크랜베리 | E3: 주의 | F3: 제한적 | G3: 와파린을 드시면 크랜베리는 피해 주세요 | H3: 크랜베리를 함께 드신 뒤 피가 잘 멎지 않는 쪽으로 수치가 올라갔다는 보고가 있습니다. 출혈 위험이 커질 수 있습니다. | I3: 요로감염 예방으로 크랜베리를 생각하신다면, 와파린 복용 사실을 알리고 다른 방법이 있는지 담당 선생님과 상의해 주세요. | L3: 임상건강기능식품학 부록 §4 p.358 | M3: 크랜베리 플라보노이드가 CYP2C9 억제 → 와파린 농도↑, INR↑ 사례보고 | N3: 이미 DB에 있는 규칙을 예시로 옮긴 것 | O3: =IF(AND(B3="",C3=""),"",IF(AND(OR(B3="",ISNUMBER(MATCH(TRIM(B3),'④ 이미 있는 성분·계열'!$A$3:$A$165,0))),OR(C3="",ISNUMBER(MATCH(TRIM(IF(ISNUMBER(FIND("/",C3)),LEFT(C3,FIND("/",C3)-1),C3)),'④ 이미 있는 성분·계열'!$A$3:$A$165,0)))),"둘 다 목록에 있음","새 성분 → 시트②에 적어 주세요")) | P3: 예시
A4: 예시2 | B4: 레보티록신 | C4: 칼슘 / 철분 | E4: 시간 조정 | F4: 확립 | G4: 갑상선약과 칼슘·철분은 4시간 띄워 드세요 | H4: 칼슘이나 철분이 갑상선약을 장에서 붙잡아 흡수를 줄입니다. 효과가 약해질 수 있습니다. | I4: 갑상선약은 아침 공복에 먼저 드시고, 칼슘·철분은 4시간 뒤에 드세요. | J4: 4 | L4: 임상건강기능식품학 부록 §4 p.372 | M4: 다가양이온이 레보티록신과 불용성 복합체 형성 | N4: B쪽 '둘 중 하나' — 칼슘만 골라도, 철분만 골라도 걸림 | O4: =IF(AND(B4="",C4=""),"",IF(AND(OR(B4="",ISNUMBER(MATCH(TRIM(B4),'④ 이미 있는 성분·계열'!$A$3:$A$165,0))),OR(C4="",ISNUMBER(MATCH(TRIM(IF(ISNUMBER(FIND("/",C4)),LEFT(C4,FIND("/",C4)-1),C4)),'④ 이미 있는 성분·계열'!$A$3:$A$165,0)))),"둘 다 목록에 있음","새 성분 → 시트②에 적어 주세요")) | P4: 예시
A5: 예시3 | B5: 항혈소판제 | C5: 은행잎 | D5: 수술 예정 | E5: 주의 | F5: 확립 | G5: 수술 전에는 은행잎을 미리 끊어 주세요 | H5: 은행잎은 피를 묽게 하는 쪽으로 작용합니다. 피를 묽게 하는 약과 겹치면 수술 중 출혈이 늘 수 있습니다. | I5: 수술 날짜가 잡혀 있다면 적어도 1주일 전에는 은행잎 제품을 멈추고, 드시고 있다는 사실을 수술팀에 알려 주세요. | K5: 7 | L5: 임상건강기능식품학 부록 §4 p.377 | M5: 은행잎 테르펜락톤의 PAF 길항 → 혈소판 응집 억제 가산 | N5: 조건이 있는 규칙의 예 — 수술 예정일 때만 이 문구가 나감 | O5: =IF(AND(B5="",C5=""),"",IF(AND(OR(B5="",ISNUMBER(MATCH(TRIM(B5),'④ 이미 있는 성분·계열'!$A$3:$A$165,0))),OR(C5="",ISNUMBER(MATCH(TRIM(IF(ISNUMBER(FIND("/",C5)),LEFT(C5,FIND("/",C5)-1),C5)),'④ 이미 있는 성분·계열'!$A$3:$A$165,0)))),"둘 다 목록에 있음","새 성분 → 시트②에 적어 주세요")) | P5: 예시
A6: 1 | O6: =IF(AND(B6="",C6=""),"",IF(AND(OR(B6="",ISNUMBER(MATCH(TRIM(B6),'④ 이미 있는 성분·계열'!$A$3:$A$165,0))),OR(C6="",ISNUMBER(MATCH(TRIM(IF(ISNUMBER(FIND("/",C6)),LEFT(C6,FIND("/",C6)-1),C6)),'④ 이미 있는 성분·계열'!$A$3:$A$165,0)))),"둘 다 목록에 있음","새 성분 → 시트②에 적어 주세요"))
A7: 2 | O7: =IF(AND(B7="",C7=""),"",IF(AND(OR(B7="",ISNUMBER(MATCH(TRIM(B7),'④ 이미 있는 성분·계열'!$A$3:$A$165,0))),OR(C7="",ISNUMBER(MATCH(TRIM(IF(ISNUMBER(FIND("/",C7)),LEFT(C7,FIND("/",C7)-1),C7)),'④ 이미 있는 성분·계열'!$A$3:$A$165,0)))),"둘 다 목록에 있음","새 성분 → 시트②에 적어 주세요"))
A8: 3 | O8: =IF(AND(B8="",C8=""),"",IF(AND(OR(B8="",ISNUMBER(MATCH(TRIM(B8),'④ 이미 있는 성분·계열'!$A$3:$A$165,0))),OR(C8="",ISNUMBER(MATCH(TRIM(IF(ISNUMBER(FIND("/",C8)),LEFT(C8,FIND("/",C8)-1),C8)),'④ 이미 있는 성분·계열'!$A$3:$A$165,0)))),"둘 다 목록에 있음","새 성분 → 시트②에 적어 주세요"))
A9: 4 | O9: =IF(AND(B9="",C9=""),"",IF(AND(OR(B9="",ISNUMBER(MATCH(TRIM(B9),'④ 이미 있는 성분·계열'!$A$3:$A$165,0))),OR(C9="",ISNUMBER(MATCH(TRIM(IF(ISNUMBER(FIND("/",C9)),LEFT(C9,FIND("/",C9)-1),C9)),'④ 이미 있는 성분·계열'!$A$3:$A$165,0)))),"둘 다 목록에 있음","새 성분 → 시트②에 적어 주세요"))
A10: 5 | O10: =IF(AND(B10="",C10=""),"",IF(AND(OR(B10="",ISNUMBER(MATCH(TRIM(B10),'④ 이미 있는 성분·계열'!$A$3:$A$165,0))),OR(C10="",ISNUMBER(MATCH(TRIM(IF(ISNUMBER(FIND("/",C10)),LEFT(C10,FIND("/",C10)-1),C10)),'④ 이미 있는 성분·계열'!$A$3:$A$165,0)))),"둘 다 목록에 있음","새 성분 → 시트②에 적어 주세요"))
A11: 6 | O11: =IF(AND(B11="",C11=""),"",IF(AND(OR(B11="",ISNUMBER(MATCH(TRIM(B11),'④ 이미 있는 성분·계열'!$A$3:$A$165,0))),OR(C11="",ISNUMBER(MATCH(TRIM(IF(ISNUMBER(FIND("/",C11)),LEFT(C11,FIND("/",C11)-1),C11)),'④ 이미 있는 성분·계열'!$A$3:$A$165,0)))),"둘 다 목록에 있음","새 성분 → 시트②에 적어 주세요"))
A12: 7 | O12: =IF(AND(B12="",C12=""),"",IF(AND(OR(B12="",ISNUMBER(MATCH(TRIM(B12),'④ 이미 있는 성분·계열'!$A$3:$A$165,0))),OR(C12="",ISNUMBER(MATCH(TRIM(IF(ISNUMBER(FIND("/",C12)),LEFT(C12,FIND("/",C12)-1),C12)),'④ 이미 있는 성분·계열'!$A$3:$A$165,0)))),"둘 다 목록에 있음","새 성분 → 시트②에 적어 주세요"))
A13: 8 | O13: =IF(AND(B13="",C13=""),"",IF(AND(OR(B13="",ISNUMBER(MATCH(TRIM(B13),'④ 이미 있는 성분·계열'!$A$3:$A$165,0))),OR(C13="",ISNUMBER(MATCH(TRIM(IF(ISNUMBER(FIND("/",C13)),LEFT(C13,FIND("/",C13)-1),C13)),'④ 이미 있는 성분·계열'!$A$3:$A$165,0)))),"둘 다 목록에 있음","새 성분 → 시트②에 적어 주세요"))
A14: 9 | O14: =IF(AND(B14="",C14=""),"",IF(AND(OR(B14="",ISNUMBER(MATCH(TRIM(B14),'④ 이미 있는 성분·계열'!$A$3:$A$165,0))),OR(C14="",ISNUMBER(MATCH(TRIM(IF(ISNUMBER(FIND("/",C14)),LEFT(C14,FIND("/",C14)-1),C14)),'④ 이미 있는 성분·계열'!$A$3:$A$165,0)))),"둘 다 목록에 있음","새 성분 → 시트②에 적어 주세요"))
A15: 10 | O15: =IF(AND(B15="",C15=""),"",IF(AND(OR(B15="",ISNUMBER(MATCH(TRIM(B15),'④ 이미 있는 성분·계열'!$A$3:$A$165,0))),OR(C15="",ISNUMBER(MATCH(TRIM(IF(ISNUMBER(FIND("/",C15)),LEFT(C15,FIND("/",C15)-1),C15)),'④ 이미 있는 성분·계열'!$A$3:$A$165,0)))),"둘 다 목록에 있음","새 성분 → 시트②에 적어 주세요"))
A16: 11 | O16: =IF(AND(B16="",C16=""),"",IF(AND(OR(B16="",ISNUMBER(MATCH(TRIM(B16),'④ 이미 있는 성분·계열'!$A$3:$A$165,0))),OR(C16="",ISNUMBER(MATCH(TRIM(IF(ISNUMBER(FIND("/",C16)),LEFT(C16,FIND("/",C16)-1),C16)),'④ 이미 있는 성분·계열'!$A$3:$A$165,0)))),"둘 다 목록에 있음","새 성분 → 시트②에 적어 주세요"))
A17: 12 | O17: =IF(AND(B17="",C17=""),"",IF(AND(OR(B17="",ISNUMBER(MATCH(TRIM(B17),'④ 이미 있는 성분·계열'!$A$3:$A$165,0))),OR(C17="",ISNUMBER(MATCH(TRIM(IF(ISNUMBER(FIND("/",C17)),LEFT(C17,FIND("/",C17)-1),C17)),'④ 이미 있는 성분·계열'!$A$3:$A$165,0)))),"둘 다 목록에 있음","새 성분 → 시트②에 적어 주세요"))
... A45: 40 | O45: =IF(AND(B45="",C45=""),"",IF(AND(OR(B45="",ISNUMBER(MATCH(TRIM(B45),'④ 이미 있는 성분·계열'!$A$3:$A$165,0))),OR(C45="",ISNUMBER(MATCH(TRIM(IF(ISNUMBER(FIND("/",C45)),LEFT(C45,FIND("/",C45)-1),C45)),'④ 이미 있는 성분·계열'!$A$3:$A$165,0)))),"둘 다 목록에 있음","새 성분 → 시트②에 적어 주세요"))

Sheet ② 새 성분
A1: 시트④ 목록에 없는 성분·계열만 적어 주세요. 영문명·다른 표기는 사용자가 직접 글자로 입력할 때 찾아 주는 데 쓰입니다.
A2: 한글 이름 (대표 표기) | B2: 영문 이름 | C2: 다른 표기 (쉼표로 구분) | D2: 종류 | E2: 속하는 계열 (있으면) | F2: 앱 버튼으로 바로 보이게 할까요? | G2: 출처·비고
A3: 둘록세틴 (예시 — 이미 있음) | B3: duloxetine | C3: 둘록세틴염산염, 심발타 | D3: 의약품 | E3: SNRI | F3: 아니오 — 「항우울제」 버튼이 SNRI로 풀림 | G3: 예시 줄

Sheet ③ 이미 있는 조합
A1: 데이터베이스에 이미 있는 조합 70건 (2026-10 기준). 같은 조합은 시트①에 다시 적지 말고, 고칠 점이 있으면 「의견」에 적어 주세요.
A2: 번호 | B2: 등급 | C2: 근거 수준 | D2: 조합 | E2: 무슨 일이 (화면) | F2: 어떻게 하면 (화면) | G2: 시간 간격 | H2: 출처 | I2: 의견 (고칠 점이 있으면)
A3: 1 | B3: 주의 | C3: 이론적 | D3: 항암제 × 고용량 항산화제 | E3: 고용량 비타민 C·E 같은 항산화제가 일부 항암제의 작용을 간섭할 수 있다는 우려가 있습니다. | F3: 항암치료 중에는 고용량 항산화 제품을 스스로 시작하지 마시고, 종양내과 담당 선생님께 먼저 확인해 주세요. | H3: 부록 §4 p.379
A4: 2 | B4: 주의 | C4: 엇갈림 | D4: 항혈전제 × 은행잎 | E4: 은행잎은 이명에 대한 근거가 엇갈리는 데 비해 출혈 위험은 분명합니다. 항혈전제와 겹치면 이득보다 위험이 앞섭니다. | F4: 이명이 있으시면 은행잎 대신 다른 보조 방법을 담당 선생님과 상의하시고, 갑작스러운 청력 변화는 바로 진료를 받아 주세요. | H4: 부록 §4 p.377
A5: 3 | B5: 주의 | C5: 엇갈림 | D5: 타목시펜 × 블랙코호시 | E5: 블랙코호시가 에스트로겐 경로로 작용하는지 아닌지에 대해 견해가 엇갈리고, 간독성 보고도 있습니다. 그래서 호르몬 치료를 받는 분에게는 스스로 판단해 시작하기 어려운 소재입니다. | F5: 갱년기 증상이 힘드시면 이 제품을 임의로 시작하기보다 종양내과·산부인과와 상의해 주세요. 간 수치 확인도 함께 이야기하시면 좋습니다. | H5: 부록 §3 p.350
A6: 4 | B6: 주의 | C6: 이론적 | D6: 면역억제제 × 프로바이오틱스 | E6: 면역이 낮아진 상태에서는 살아 있는 균이 드물게 혈류로 넘어가 문제를 일으킬 수 있습니다. 그래서 건강한 분과 같은 기준으로 판단하지 않습니다. | F6: 장 건강이 필요하시면 생균 제품을 스스로 고르기보다 담당 선생님과 먼저 상의해 주세요. | H6: 부록 §1 p.340
A7: 5 | B7: 주의 | C7: 제한적 | D7: 와파린 × 크랜베리 | E7: 크랜베리를 함께 드신 뒤 INR이 올라갔다는 보고가 있습니다. INR이 높아지면 출혈 위험이 커집니다. | F7: 요로감염 예방 목적으로 크랜베리를 고려하신다면, 와파린 복용 사실을 알리고 다른 방법이 있는지 담당 선생님과 먼저 상의해 주세요. | H7: 부록 §4 p.358
A8: 6 | B8: 주의 | C8: 제한적 | D8: 와파린 × 글루코사민 | E8: 관절용으로 흔히 쓰이는 글루코사민을 와파린과 함께 드신 뒤 INR이 상승한 사례가 보고되어 있습니다. INR이 높아지면 출혈 위험이 커집니다. | F8: 무릎 관절 보조가 필요하시면 담당 선생님과 다른 선택지를 상의하시고, 이미 시작하셨다면 INR을 다시 확인하는 것이 좋습니다. | H8: 부록 §4 p.354
A9: 7 | B9: 금기 | C9: 확립 | D9: 아미오다론 × 요오드 × 켈프 | E9: 아미오다론 자체가 많은 양의 요오드를 가지고 있어 갑상선 기능 이상을 일으킬 수 있습니다. 여기에 요오드를 더 넣으면 갑상선에 부담이 더해집니다. | F9: 켈프·다시마·해조류가 든 제품과 요오드 강화 종합비타민의 성분표를 확인해 주시고, 정기 갑상선기능검사를 담당 선생님과 계획해 주세요. | H9: 부록 §4 p.355
A10: 8 | B10: 금기 | C10: 확립 | D10: 항암제 × 세인트존스워트 | E10: 세인트존스워트는 여러 항암제의 대사를 촉진해 혈중 농도를 낮춥니다. 그러면 항암 효과가 떨어질 수 있습니다. | F10: 치료 중에는 어떤 건강기능식품이든 종양내과와 먼저 상의하시고, 특히 기분 개선용 수입 제품의 성분표를 확인해 주세요. | H10: 부록 §4 p.379
A11: 9 | B11: 금기 | C11: 확립 | D11: 항경련제 × 은행잎 | E11: 은행잎은 발작이 일어나는 문턱(역치)을 낮추는 것으로 정리되어 있습니다. 뇌전증이 있으신 분에게는 발작 위험이 됩니다. | F11: 기억력·혈행 제품에 은행잎이 들어 있는지 성분표를 꼭 확인해 주시고, 담당 선생님께 복용 중인 모든 제품을 알려 주세요. | H11: 부록 §4 p.365
A12: 10 | B12: 금기 | C12: 확립 | D12: 항경련제 × 카바 | E12: 카바는 항경련제를 드시는 분에게 절대 회피 대상으로 정리되어 있습니다. | F12: 긴장 완화용 수입 제품 성분표에 카바(kava)가 있는지 확인해 주시고, 담당 선생님께 알려 주세요. | H12: 부록 §4 p.365
A13: 11 | B13: 금기 | C13: 확립 | D13: 항경련제 × 세인트존스워트 | E13: 세인트존스워트가 약물 대사를 촉진해 항경련제가 빨리 분해되면, 혈중 농도가 낮아져 조절되던 발작이 다시 나타날 수 있습니다. | F13: 기분 개선용 제품의 성분표를 확인해 주시고, 담당 선생님께 복용 중인 모든 제품을 알려 주세요. | H13: 부록 §4 p.365
A14: 12 | B14: 금기 | C14: 확립 | D14: 항레트로바이러스제 × 세인트존스워트 | E14: 세인트존스워트가 프로테아제억제제·NNRTI의 혈중 농도를 낮춰 바이러스가 약에 내성을 갖게 될 수 있습니다. | F14: 새 보충제를 시작하기 전에 반드시 담당 선생님께 성분을 확인받아 주세요. | H14: 부록 §4 p.379
... A54: 52 | B54: 주의 | C54: 확립 | D54: 와파린 × 비타민 K × 비타민 K2 | E54: 와파린은 비타민 K의 작용을 막아 피를 묽게 하는 약입니다. 비타민 K를 보충하면 약의 작용이 직접 상쇄되어 INR이 낮아지고 혈전 위험이 올라갑니다. | F54: 뼈 건강용 제품에 비타민 K2(MK-7)가 들어 있는 경우가 많으니 성분표를 확인해 주세요. 뼈 보조가 필요하면 칼슘·비타민 D 위주로 담당 선생님과 상의하시고, 식사에서의 비타민 K 섭취량도 갑자기 바꾸지 않는 것이 좋습니다. | H54: 부록 §4 p.353
A55: 53 | B55: 시간 조정 | C55: 확립 | D55: 비스포스포네이트 × 칼슘 | E55: 칼슘이 비스포스포네이트와 결합해 흡수를 현저히 낮춥니다. 같이 드시면 골다공증 약이 제 역할을 하기 어려워집니다. | F55: 비스포스포네이트는 기상 직후 공복에 물 한 컵과 함께 드시고 30분 이상 앉아 계신 뒤, 칼슘은 최소 2시간 이상 지나서 점심·저녁에 나누어 드세요. | G55: 2시간 | H55: 부록 §3 p.346
A56: 54 | B56: 시간 조정 | C56: 확립 | D56: 레보티록신 × 칼슘 | E56: 칼슘이 위장관에서 레보티록신과 결합해 흡수를 방해합니다. 같이 드시면 같은 용량을 먹어도 몸에 들어오는 양이 줄어 갑상선 수치가 흔들릴 수 있습니다. | F56: 레보티록신은 아침 공복에 드시고, 칼슘은 최소 4시간 뒤로 미뤄 주세요. 종합비타민·위장약에도 칼슘이 들어 있을 수 있으니 성분표를 확인해 주세요. | G56: 4시간 | H56: 부록 §4 p.381
A57: 55 | B57: 시간 조정 | C57: 확립 | D57: 레보티록신 × 철분 | E57: 철분이 레보티록신과 위장관에서 결합해 흡수를 줄입니다. 빈혈 보충과 갑상선 치료를 같은 시간에 하면 갑상선 쪽이 손해를 봅니다. | F57: 레보티록신을 아침 공복에 드신 뒤 철분은 최소 4시간 뒤로 미뤄 주세요. 철분은 비타민 C와 함께 드시면 흡수에 도움이 됩니다. | G57: 4시간 | H57: 부록 §4 p.357
A58: 56 | B58: 시간 조정 | C58: 확립 | D58: 오를리스타트 × 오메가-3 × 비타민 A × 비타민 D × 비타민 E × 비타민 K × 코엔자임 Q10 | E58: 오를리스타트는 지방 흡수를 막는 약이라, 지방과 함께 흡수되는 성분들(오메가-3, 비타민 A·D·E·K, 코엔자임 Q10)도 함께 덜 흡수됩니다. | F58: 지용성 보충제는 오를리스타트 복용 시각에서 2시간 이상 띄워(예: 취침 전) 드시고, 지용성 비타민은 별도로 보충하는 것이 좋습니다. | G58: 2시간 | H58: 부록 §4 p.381
A59: 57 | B59: 시간 조정 | C59: 확립 | D59: 프로바이오틱스 × 항생제 | E59: 항생제는 나쁜 균만 골라 죽이지 못하기 때문에, 같은 시간에 먹은 유산균도 함께 사멸됩니다. 그러면 제품을 먹어도 장까지 살아서 가는 균이 크게 줄어듭니다. | F59: 항생제 복용 시각에서 최소 2시간을 띄워 유산균을 드시고, 항생제가 끝난 뒤에도 1~4주가량 이어서 드시면 장내 균총 회복에 도움이 됩니다. | G59: 2시간 | H59: 부록 §3 p.344
A60: 58 | B60: 시간 조정 | C60: 확립 | D60: 레보티록신 × 콩 | E60: 콩 성분이 위장관에서 레보티록신의 흡수를 방해합니다. 같은 시간에 드시면 갑상선호르몬이 충분히 흡수되지 않을 수 있습니다. | F60: 레보티록신은 공복에 드시고, 콩 단백·이소플라본 제품은 최소 4시간 뒤로 미뤄 주세요. | G60: 4시간 | H60: 부록 §4 p.357
A61: 59 | B61: 확인 권장 | C61: 이론적 | D61: 항응고제 × 커큐민 | E61: 커큐민은 혈소판이 뭉치는 것을 억제하는 경향이 있고 담즙 자극 가능성도 있습니다. 항응고제와 겹치면 출혈 경향이 더해질 수 있습니다. | F61: 관절·염증 목적으로 고함량 커큐민을 고려하신다면 담당 선생님께 항응고제 복용 사실을 먼저 알려 주세요. 담석이 있으신 분도 신중해야 합니다. | H61: 부록 §4 p.368
A62: 60 | B62: 확인 권장 | C62: 확립 | D62: 비오틴 | E62: 비오틴은 검사 시약의 반응을 방해해, 실제 몸 상태와 다른 수치가 나오게 만들 수 있습니다. 갑상선기능검사나 심근표지자 검사에서 특히 문제가 됩니다. | F62: 혈액검사 예정이 있으면 비오틴이 든 모발·손톱용 제품과 종합비타민을 검사 전에 잠시 쉬어 주시고, 채혈 전에 복용 사실을 꼭 알려 주세요. | H62: 부록 §4 p.381
A63: 61 | B63: 확인 권장 | C63: 이론적 | D63: 피나스테리드 × 쏘팔메토 | E63: 쏘팔메토는 남성호르몬 작용을 억제하는 경향이 있어 피나스테리드와 방향이 겹칩니다. 또 전립선 검사(PSA) 수치 해석에 영향을 줄 수 있습니다. | F63: 탈모나 전립선 목적으로 쏘팔메토를 고려하신다면 담당 선생님과 상의하시고, PSA 검사 전에는 복용 사실을 꼭 알려 주세요. | H63: 부록 §4 p.378
A64: 62 | B64: 확인 권장 | C64: 이론적 | D64: GLP-1 수용체작용제 × 글루코사민 | E64: GLP-1 제제는 위 배출을 늦춰 오심·포만감·변비나 설사가 흔합니다. 여기에 위장에 부담이 되는 보충제를 더하면 증상이 겹쳐 힘들어질 수 있습니다. | F64: 관절 보조가 필요하시면 위장 부담이 적은 형태를 담당 선생님과 상의하시고, 새 제품은 한 번에 여러 종을 시작하지 말고 한 가지씩 천천히 도입해 주세요. | H64: 부록 §4 p.357
A65: 63 | B65: 확인 권장 | C65: 확립 | D65: 레보도파 × 단백질 × 철분 | E65: 단백질과 철분은 레보도파가 몸에 흡수되는 것을 방해합니다. 같은 시간에 드시면 약효가 고르지 않게 느껴질 수 있습니다. | F65: 레보도파와 단백질 보충제·철분은 복용 시간을 서로 떨어뜨려 주세요. 어느 정도 간격이 적절한지는 담당 선생님과 상의해 정하시면 좋습니다. | H65: 부록 §4 p.381
A66: 64 | B66: 확인 권장 | C66: 확립 | D66: 메트포르민 × 비타민 B12 | E66: 메트포르민 장기 복용은 비타민 B12 흡수 저하와 연관됩니다. B12가 부족하면 피로나 손발 저림 같은 신경 증상이 생길 수 있습니다. | F66: 장기 복용 중이시면 B12 수치를 확인하고 보충이 필요한지 담당 선생님과 상의해 주세요. | H66: 부록 §4 p.381
A67: 65 | B67: 확인 권장 | C67: 확립 | D67: PPI × 비타민 B12 × 마그네슘 × 칼슘 × 철분 | E67: PPI는 위산을 줄이는 약인데, 이 영양소들은 위산이 있어야 잘 흡수됩니다. 장기 복용하면 부족해질 수 있습니다. | F67: 장기 복용 중이시면 보충이 필요한지 담당 선생님과 상의해 주세요. 위산이 낮은 상태에서는 구연산칼슘 형태가 흡수에 유리합니다. | H67: 부록 §4 p.381
A68: 66 | B68: 확인 권장 | C68: 확립 | D68: 홍경천 × 인삼 | E68: 두 소재 모두 어댑토젠으로 스트레스 적응을 돕지만 자극·각성 작용도 함께 가집니다. 겹치면 잠이 안 오거나 가슴이 두근거리고 과하게 흥분될 수 있습니다. | F68: 중요한 일정 직전에 처음 드시지 마시고, 평소에 미리 소량으로 반응을 확인해 보세요. 자가면역·갑상선 질환이 있으시면 먼저 상의가 필요합니다. | H68: 부록 §3 p.345
A69: 67 | B69: 확인 권장 | C69: 제한적 | D69: 와파린 × 코엔자임 Q10 | E69: 코엔자임 Q10이 와파린의 항응고 효과를 다소 떨어뜨릴 수 있다는 점이 지적되어 있습니다. | F69: 피로·근육통 때문에 코엔자임 Q10을 고려하신다면 담당 선생님께 알리고, 시작 후 INR을 다시 확인하도록 상의해 주세요. | H69: 부록 §4 p.381
A70: 68 | B70: 확인 권장 | C70: 확립 | D70: 아연 × 구리 | E70: 아연과 구리는 흡수 경로에서 서로 경쟁합니다. 아연만 오래 많이 드시면 구리가 부족해질 수 있습니다. | F70: 장기 복용이 필요하시면 구리가 함께 든 제품을 고르거나, 적정 용량을 담당 선생님·약사와 상의해 주세요. | H70: 부록 §2 p.341
A71: 69 | B71: 알아두기 | C71: 확립 | D71: 사카로마이세스 보울라디 × 항생제 | E71: 일반 유산균은 세균이라 항생제에 함께 죽지만, 사카로마이세스 보울라디는 효모여서 항생제에 사멸되지 않습니다. 항생제 유발 설사 예방 근거도 있습니다. | F71: 항생제 복용 중 설사가 걱정되신다면 이 균주를 약사와 상의해 보실 수 있습니다. 다만 면역이 낮거나 중증 기저질환이 있으시면 먼저 상의가 필요합니다. | H71: 부록 §3 p.344
A72: 70 | B72: 알아두기 | C72: 엇갈림 | D72: 코엔자임 Q10 × 스타틴 | E72: 스타틴이 막는 효소는 콜레스테롤뿐 아니라 코엔자임 Q10을 만드는 경로에도 관여합니다. 그래서 스타틴을 드시면 코엔자임 Q10이 줄어들 수 있고, 이것이 근육통·피로와 연결될 수 있다고 봅니다. | F72: 근육통이 있으시면 코엔자임 Q10 보충을 담당 선생님과 상의해 보실 수 있습니다. 다만 효과에 대한 연구 결과는 엇갈립니다. | H72: 부록 §3 p.343

Sheet ④ 이미 있는 성분·계열
A1: 데이터베이스에 이미 있는 성분·계열 이름 (약학검수시트 v1 기준 163개). 시트①에 적을 때 이 표기를 그대로 쓰세요.
A2: 이름 (이 표기 그대로) | B2: 종류
A3: 5-HTP | B3: 기타
A4: MSM | B4: 기타
A5: NAC | B5: 기타
A6: 감마-아미노부티르산 | B6: 기타
A7: 감마리놀렌산 | B7: 기타
A8: 고용량 항산화제 | B8: 기타
A9: 글루코사민 | B9: 기타
A10: 글리신 | B10: 기타
A11: 나토키나제 | B11: 기타
A12: 난소화성 말토덱스트린 | B12: 기타
A13: 다가양이온 | B13: 기타
... A165: 프로바이오틱스 | B165: 프로바이오틱스

Sheet ⑤ 용어
A1: A. 등급 (심각도) — 시트① 「등급」 드롭다운
A2: 등급 | B2: DB 값(개발자용) | C2: 뜻 | D2: 예
A3: 금기 | B3: contraindicated | C3: 함께 쓰면 안 됨. 둘 중 하나를 빼야 함. | D3: 아미오다론 × 요오드·켈프
A4: 주의 | B4: caution | C4: 같이 쓰면 해로울 수 있어 의사·약사 상의가 필요함. | D4: 와파린 × 크랜베리
A5: 시간 조정 | B5: timing | C5: 같이 써도 되지만 복용 시간을 띄워야 함. 「시간 간격」 칸을 꼭 채움. | D5: 레보티록신 × 칼슘 (4시간)
A6: 확인 권장 | B6: monitor | C6: 함께 쓸 수 있으나 검사 수치·증상을 지켜봐야 함. | D6: 스타틴 × 홍국
A7: 알아두기 | B7: info | C7: 위험은 낮고 알아 두면 좋은 정보. | D7: 비타민 C × 철분 (흡수 도움)
A10: B. 근거 수준 — 시트① 「근거 수준」 드롭다운
A11: 근거 수준 | B11: DB 값(개발자용) | C11: 뜻 | D11: 화면에 보이는 표기
A12: 확립 | B12: established | C12: 임상 연구·공식 자료로 확인됨 | D12: 연구로 확인됨
A13: 이론적 | B13: theoretical | C13: 기전상 예상되나 사람에서 확인되지 않음 | D13: 가능성 있음
A14: 제한적 | B14: limited | C14: 사례 보고 몇 건 수준 | D14: 가능성 있음
A15: 엇갈림 | B15: conflicting | C15: 연구 결과가 서로 다름 | D15: 의견이 갈림
A18: C. 조건 (해당할 때만) — 시트① 「조건」 드롭다운
A19: 조건 이름 | B19: 비고
A20: 임신 | B20: 앱 버튼 「임신·수유 중」이 이 조건으로 전달됨
A21: 만성콩팥병(3~4기·중증) | B21: 앱 버튼 「신장질환」은 아직 연결 안 됨 — 신장 조건 규칙을 적어 주시면 연결함
A22: 혈액투석
A23: 흡연
A24: 수술 예정 | B24: 「수술 전 중단」 일수와 함께 쓰는 조건
A25: 간질환 | B25: 데이터베이스에 아직 없음 — 적어 주시면 새로 만듦
A26: 60대 이상 | B26: 데이터베이스에 아직 없음 — 고령 조건 규칙이 있으면 적어 주시면 새로 만듦
A29: D. 앱 화면의 버튼(칩) — 사용자가 누르는 이름과 데이터베이스 성분·계열의 대응
A30: 앱 버튼 | B30: 데이터베이스에서 풀리는 이름 / 상태
A31: 오메가3 | B31: 같은 이름의 성분 있음
A32: 비타민D | B32: 같은 이름의 성분 있음
A33: 마그네슘 | B33: 같은 이름의 성분 있음
A34: 유산균 | B34: =프로바이오틱스
A35: 종합비타민 | B35: 연결된 규칙 없음
A36: 철분 | B36: 같은 이름의 성분 있음
A37: 루테인 | B37: 같은 이름의 성분 있음
A38: 밀크씨슬 | B38: 같은 이름의 성분 있음
A39: 콜라겐 | B39: 연결된 규칙 없음
A40: 아연 | B40: 같은 이름의 성분 있음
A41: 홍삼 | B41: =인삼
A42: 단백질보충제 | B42: =콩
A43: 갑상선약 | B43: =레보티록신
A44: 혈압약 | B44: =칼슘통로차단제·RAS차단제·칼륨보존이뇨제
A45: 고지혈증약 | B45: =스타틴
A46: 위장약 | B46: =PPI
...
